Traceback (most recent call last):
  File "/scratch/gpfs/GEOCLIM/LRGROUP/maximek/INMOS/samudra-bgc/src/train.py", line 631, in <module>
    main()
  File "/scratch/gpfs/GEOCLIM/LRGROUP/maximek/INMOS/samudra-bgc/src/train.py", line 621, in main
    trainer = Trainer(cfg)
  File "/scratch/gpfs/GEOCLIM/LRGROUP/maximek/INMOS/samudra-bgc/src/train.py", line 64, in __init__
    init_distributed_mode(cfg.distributed)
  File "/scratch/gpfs/GEOCLIM/LRGROUP/maximek/INMOS/samudra-bgc/src/utils/distributed.py", line 105, in init_distributed_mode
    torch.cuda.set_device(cfg.gpu)
  File "/home/mk0964/.conda/envs/samudra/lib/python3.10/site-packages/torch/cuda/__init__.py", line 408, in set_device
    torch._C._cuda_setDevice(device)
RuntimeError: CUDA error: invalid device ordinal
CUDA kernel errors might be asynchronously reported at some other API call, so the stacktrace below might be incorrect.
For debugging consider passing CUDA_LAUNCH_BLOCKING=1.
Compile with `TORCH_USE_CUDA_DSA` to enable device-side assertions.

Traceback (most recent call last):
  File "/scratch/gpfs/GEOCLIM/LRGROUP/maximek/INMOS/samudra-bgc/src/train.py", line 631, in <module>
    main()
  File "/scratch/gpfs/GEOCLIM/LRGROUP/maximek/INMOS/samudra-bgc/src/train.py", line 621, in main
    trainer = Trainer(cfg)
  File "/scratch/gpfs/GEOCLIM/LRGROUP/maximek/INMOS/samudra-bgc/src/train.py", line 64, in __init__
    init_distributed_mode(cfg.distributed)
  File "/scratch/gpfs/GEOCLIM/LRGROUP/maximek/INMOS/samudra-bgc/src/utils/distributed.py", line 105, in init_distributed_mode
    torch.cuda.set_device(cfg.gpu)
  File "/home/mk0964/.conda/envs/samudra/lib/python3.10/site-packages/torch/cuda/__init__.py", line 408, in set_device
    torch._C._cuda_setDevice(device)
RuntimeError: CUDA error: invalid device ordinal
CUDA kernel errors might be asynchronously reported at some other API call, so the stacktrace below might be incorrect.
For debugging consider passing CUDA_LAUNCH_BLOCKING=1.
Compile with `TORCH_USE_CUDA_DSA` to enable device-side assertions.

[2025-09-05 22:46:14,251] torch.distributed.elastic.multiprocessing.api: [WARNING] Sending process 179600 closing signal SIGTERM
[2025-09-05 22:46:14,251] torch.distributed.elastic.multiprocessing.api: [WARNING] Sending process 179601 closing signal SIGTERM
[2025-09-05 22:46:14,480] torch.distributed.elastic.multiprocessing.api: [ERROR] failed (exitcode: 1) local_rank: 2 (pid: 179602) of binary: /home/mk0964/.conda/envs/samudra/bin/python
Traceback (most recent call last):
  File "/home/mk0964/.conda/envs/samudra/bin/torchrun", line 8, in <module>
    sys.exit(main())
  File "/home/mk0964/.conda/envs/samudra/lib/python3.10/site-packages/torch/distributed/elastic/multiprocessing/errors/__init__.py", line 347, in wrapper
    return f(*args, **kwargs)
  File "/home/mk0964/.conda/envs/samudra/lib/python3.10/site-packages/torch/distributed/run.py", line 812, in main
    run(args)
  File "/home/mk0964/.conda/envs/samudra/lib/python3.10/site-packages/torch/distributed/run.py", line 803, in run
    elastic_launch(
  File "/home/mk0964/.conda/envs/samudra/lib/python3.10/site-packages/torch/distributed/launcher/api.py", line 135, in __call__
    return launch_agent(self._config, self._entrypoint, list(args))
  File "/home/mk0964/.conda/envs/samudra/lib/python3.10/site-packages/torch/distributed/launcher/api.py", line 268, in launch_agent
    raise ChildFailedError(
torch.distributed.elastic.multiprocessing.errors.ChildFailedError: 
============================================================
src/train.py FAILED
------------------------------------------------------------
Failures:
[1]:
  time      : 2025-09-05_22:46:14
  host      : tiger-i04g1
  rank      : 3 (local_rank: 3)
  exitcode  : 1 (pid: 179603)
  error_file: <N/A>
  traceback : To enable traceback see: https://pytorch.org/docs/stable/elastic/errors.html
------------------------------------------------------------
Root Cause (first observed failure):
[0]:
  time      : 2025-09-05_22:46:14
  host      : tiger-i04g1
  rank      : 2 (local_rank: 2)
  exitcode  : 1 (pid: 179602)
  error_file: <N/A>
  traceback : To enable traceback see: https://pytorch.org/docs/stable/elastic/errors.html
============================================================
