Traceback (most recent call last):
  File "/scratch/gpfs/GEOCLIM/LRGROUP/maximek/INMOS/samudra-bgc/src/train.py", line 12, in <module>
Traceback (most recent call last):
Traceback (most recent call last):
  File "/scratch/gpfs/GEOCLIM/LRGROUP/maximek/INMOS/samudra-bgc/src/train.py", line 12, in <module>
Traceback (most recent call last):
  File "/scratch/gpfs/GEOCLIM/LRGROUP/maximek/INMOS/samudra-bgc/src/train.py", line 12, in <module>
      File "/scratch/gpfs/GEOCLIM/LRGROUP/maximek/INMOS/samudra-bgc/src/train.py", line 12, in <module>
import dask
ModuleNotFoundError: No module named 'dask'    
import dask
    import dask
ModuleNotFoundError: No module named 'dask'    
import daskModuleNotFoundError
: No module named 'dask'
ModuleNotFoundError: No module named 'dask'
[2025-09-05 22:00:13,684] torch.distributed.elastic.multiprocessing.api: [ERROR] failed (exitcode: 1) local_rank: 0 (pid: 162836) of binary: /home/mk0964/.conda/envs/samudra-bgc/bin/python
Traceback (most recent call last):
  File "/home/mk0964/.conda/envs/samudra-bgc/bin/torchrun", line 33, in <module>
    sys.exit(load_entry_point('torch==2.2.1', 'console_scripts', 'torchrun')())
             ^^^^^^^^^^^^^^^^^^^^^^^^^^^^^^^^^^^^^^^^^^^^^^^^^^^^^^^^^^^^^^^^^
  File "/home/mk0964/.conda/envs/samudra-bgc/lib/python3.12/site-packages/torch/distributed/elastic/multiprocessing/errors/__init__.py", line 347, in wrapper
    return f(*args, **kwargs)
           ^^^^^^^^^^^^^^^^^^
  File "/home/mk0964/.conda/envs/samudra-bgc/lib/python3.12/site-packages/torch/distributed/run.py", line 812, in main
    run(args)
  File "/home/mk0964/.conda/envs/samudra-bgc/lib/python3.12/site-packages/torch/distributed/run.py", line 803, in run
    elastic_launch(
  File "/home/mk0964/.conda/envs/samudra-bgc/lib/python3.12/site-packages/torch/distributed/launcher/api.py", line 135, in __call__
    return launch_agent(self._config, self._entrypoint, list(args))
           ^^^^^^^^^^^^^^^^^^^^^^^^^^^^^^^^^^^^^^^^^^^^^^^^^^^^^^^^
  File "/home/mk0964/.conda/envs/samudra-bgc/lib/python3.12/site-packages/torch/distributed/launcher/api.py", line 268, in launch_agent
    raise ChildFailedError(
torch.distributed.elastic.multiprocessing.errors.ChildFailedError: 
============================================================
src/train.py FAILED
------------------------------------------------------------
Failures:
[1]:
  time      : 2025-09-05_22:00:13
  host      : tiger-i04g1
  rank      : 1 (local_rank: 1)
  exitcode  : 1 (pid: 162837)
  error_file: <N/A>
  traceback : To enable traceback see: https://pytorch.org/docs/stable/elastic/errors.html
[2]:
  time      : 2025-09-05_22:00:13
  host      : tiger-i04g1
  rank      : 2 (local_rank: 2)
  exitcode  : 1 (pid: 162838)
  error_file: <N/A>
  traceback : To enable traceback see: https://pytorch.org/docs/stable/elastic/errors.html
[3]:
  time      : 2025-09-05_22:00:13
  host      : tiger-i04g1
  rank      : 3 (local_rank: 3)
  exitcode  : 1 (pid: 162839)
  error_file: <N/A>
  traceback : To enable traceback see: https://pytorch.org/docs/stable/elastic/errors.html
------------------------------------------------------------
Root Cause (first observed failure):
[0]:
  time      : 2025-09-05_22:00:13
  host      : tiger-i04g1
  rank      : 0 (local_rank: 0)
  exitcode  : 1 (pid: 162836)
  error_file: <N/A>
  traceback : To enable traceback see: https://pytorch.org/docs/stable/elastic/errors.html
============================================================
