Traceback (most recent call last):
  File "/scratch/gpfs/GEOCLIM/LRGROUP/maximek/INMOS/samudra-bgc/src/train.py", line 631, in <module>
Traceback (most recent call last):
  File "/scratch/gpfs/GEOCLIM/LRGROUP/maximek/INMOS/samudra-bgc/src/train.py", line 631, in <module>
    main()
  File "/scratch/gpfs/GEOCLIM/LRGROUP/maximek/INMOS/samudra-bgc/src/train.py", line 621, in main
Traceback (most recent call last):
      File "/scratch/gpfs/GEOCLIM/LRGROUP/maximek/INMOS/samudra-bgc/src/train.py", line 631, in <module>
trainer = Trainer(cfg)
         main() 
        ^  File "/scratch/gpfs/GEOCLIM/LRGROUP/maximek/INMOS/samudra-bgc/src/train.py", line 621, in main
^^^Traceback (most recent call last):
^^^^  File "/scratch/gpfs/GEOCLIM/LRGROUP/maximek/INMOS/samudra-bgc/src/train.py", line 631, in <module>
^^^^
  File "/scratch/gpfs/GEOCLIM/LRGROUP/maximek/INMOS/samudra-bgc/src/train.py", line 126, in __init__
    main()
  File "/scratch/gpfs/GEOCLIM/LRGROUP/maximek/INMOS/samudra-bgc/src/train.py", line 621, in main
    trainer = Trainer(cfg)
    self.data, self.data_mean, self.data_std = validate_data(
                        trainer = Trainer(cfg)      
main()  
    ^  ^    File "/scratch/gpfs/GEOCLIM/LRGROUP/maximek/INMOS/samudra-bgc/src/train.py", line 621, in main
^  ^  ^  ^  ^  ^  ^  ^  ^      ^ trainer = Trainer(cfg) 
 
  ^  File "/scratch/gpfs/GEOCLIM/LRGROUP/maximek/INMOS/samudra-bgc/src/train.py", line 126, in __init__
 ^  ^  ^  ^  ^      ^self.data, self.data_mean, self.data_std = validate_data(  ^
  ^  ^   ^   ^   
        File "/scratch/gpfs/GEOCLIM/LRGROUP/maximek/INMOS/samudra-bgc/src/train.py", line 126, in __init__
    ^  ^  ^      ^  self.data, self.data_mean, self.data_std = validate_data(^  
^^ ^^  ^^  ^^  ^^  ^^  ^^  
^  ^  File "/scratch/gpfs/GEOCLIM/LRGROUP/maximek/INMOS/samudra-bgc/src/train.py", line 126, in __init__
  ^  ^  ^  ^      ^  self.data, self.data_mean, self.data_std = validate_data(
  
    File "/scratch/gpfs/GEOCLIM/LRGROUP/maximek/INMOS/samudra-bgc/src/utils/data.py", line 160, in validate_data
                       ).rename({"x": "lon", "y": "lat"})   
                                 ^   ^   ^  ^^  ^^  ^^  ^^  ^^  ^^  ^^  ^^  ^^  ^^  ^^  ^^  ^^  ^^^ 
^^ ^^   File "/scratch/gpfs/GEOCLIM/LRGROUP/maximek/INMOS/samudra-bgc/src/utils/data.py", line 160, in validate_data
^^ ^^ ^^ ^^ ^^     ^^ ).rename({"x": "lon", "y": "lat"})^^ 
^^ ^^ ^^  ^^  ^
  ^^ 
^   File "/scratch/gpfs/GEOCLIM/LRGROUP/maximek/INMOS/samudra-bgc/src/utils/data.py", line 160, in validate_data
^   File "/home/mk0964/.conda/envs/samudra-bgc/lib/python3.12/site-packages/xarray/core/dataset.py", line 3975, in rename
^^^^^^^^^^^    ^^).rename({"x": "lon", "y": "lat"})^^
^^^^^^^ 
^ ^   File "/scratch/gpfs/GEOCLIM/LRGROUP/maximek/INMOS/samudra-bgc/src/utils/data.py", line 160, in validate_data
^ ^ ^ ^^^^^^^    ^^).rename({"x": "lon", "y": "lat"})^^
^^^^^^^ ^^ ^^ ^^ ^^ ^^ ^^^^^^
^^^^  File "/home/mk0964/.conda/envs/samudra-bgc/lib/python3.12/site-packages/xarray/core/dataset.py", line 3975, in rename
^^^^^^^^^^^^^^^^^^^^^^^^^^^^
^^  File "/home/mk0964/.conda/envs/samudra-bgc/lib/python3.12/site-packages/xarray/core/dataset.py", line 3975, in rename
^^^^^^^^^^^^
  File "/home/mk0964/.conda/envs/samudra-bgc/lib/python3.12/site-packages/xarray/core/dataset.py", line 3975, in rename
            return self._rename(name_dict=name_dict, **names)return self._rename(name_dict=name_dict, **names)return self._rename(name_dict=name_dict, **names)

    
return self._rename(name_dict=name_dict, **names)
                                       ^  ^^  ^^ ^^^^^^^^^^^^^^^^^^^^^^^^^^^^^^^^^^^^^^^^^^^^^^^^^^^^^^^^^^^^^^^^^^^^^^^^^^^^^^^^^^^^^^^^^^^^^^^^^^^^^^^^^^^^^^^^^^^^^^^^^^^^^^^^^^^^^^^^^^^^^^^^^^^^^^^^^^^^^^
^^
^^  File "/home/mk0964/.conda/envs/samudra-bgc/lib/python3.12/site-packages/xarray/core/dataset.py", line 3916, in _rename
^
  File "/home/mk0964/.conda/envs/samudra-bgc/lib/python3.12/site-packages/xarray/core/dataset.py", line 3916, in _rename

  File "/home/mk0964/.conda/envs/samudra-bgc/lib/python3.12/site-packages/xarray/core/dataset.py", line 3916, in _rename
  File "/home/mk0964/.conda/envs/samudra-bgc/lib/python3.12/site-packages/xarray/core/dataset.py", line 3916, in _rename
    raise ValueError(
ValueError: cannot rename 'x' because it is not a variable or dimension in this dataset
    raise ValueError(
ValueError:     cannot rename 'x' because it is not a variable or dimension in this datasetraise ValueError(

    raise ValueError(ValueError
: cannot rename 'x' because it is not a variable or dimension in this datasetValueError
: cannot rename 'x' because it is not a variable or dimension in this dataset
[2025-09-05 18:00:10,762] torch.distributed.elastic.multiprocessing.api: [ERROR] failed (exitcode: 1) local_rank: 0 (pid: 108788) of binary: /home/mk0964/.conda/envs/samudra-bgc/bin/python
Traceback (most recent call last):
  File "/home/mk0964/.conda/envs/samudra-bgc/bin/torchrun", line 33, in <module>
    sys.exit(load_entry_point('torch==2.2.1', 'console_scripts', 'torchrun')())
             ^^^^^^^^^^^^^^^^^^^^^^^^^^^^^^^^^^^^^^^^^^^^^^^^^^^^^^^^^^^^^^^^^
  File "/home/mk0964/.conda/envs/samudra-bgc/lib/python3.12/site-packages/torch/distributed/elastic/multiprocessing/errors/__init__.py", line 347, in wrapper
    return f(*args, **kwargs)
           ^^^^^^^^^^^^^^^^^^
  File "/home/mk0964/.conda/envs/samudra-bgc/lib/python3.12/site-packages/torch/distributed/run.py", line 812, in main
    run(args)
  File "/home/mk0964/.conda/envs/samudra-bgc/lib/python3.12/site-packages/torch/distributed/run.py", line 803, in run
    elastic_launch(
  File "/home/mk0964/.conda/envs/samudra-bgc/lib/python3.12/site-packages/torch/distributed/launcher/api.py", line 135, in __call__
    return launch_agent(self._config, self._entrypoint, list(args))
           ^^^^^^^^^^^^^^^^^^^^^^^^^^^^^^^^^^^^^^^^^^^^^^^^^^^^^^^^
  File "/home/mk0964/.conda/envs/samudra-bgc/lib/python3.12/site-packages/torch/distributed/launcher/api.py", line 268, in launch_agent
    raise ChildFailedError(
torch.distributed.elastic.multiprocessing.errors.ChildFailedError: 
============================================================
src/train.py FAILED
------------------------------------------------------------
Failures:
[1]:
  time      : 2025-09-05_18:00:10
  host      : tiger-i04g1
  rank      : 1 (local_rank: 1)
  exitcode  : 1 (pid: 108789)
  error_file: <N/A>
  traceback : To enable traceback see: https://pytorch.org/docs/stable/elastic/errors.html
[2]:
  time      : 2025-09-05_18:00:10
  host      : tiger-i04g1
  rank      : 2 (local_rank: 2)
  exitcode  : 1 (pid: 108790)
  error_file: <N/A>
  traceback : To enable traceback see: https://pytorch.org/docs/stable/elastic/errors.html
[3]:
  time      : 2025-09-05_18:00:10
  host      : tiger-i04g1
  rank      : 3 (local_rank: 3)
  exitcode  : 1 (pid: 108791)
  error_file: <N/A>
  traceback : To enable traceback see: https://pytorch.org/docs/stable/elastic/errors.html
------------------------------------------------------------
Root Cause (first observed failure):
[0]:
  time      : 2025-09-05_18:00:10
  host      : tiger-i04g1
  rank      : 0 (local_rank: 0)
  exitcode  : 1 (pid: 108788)
  error_file: <N/A>
  traceback : To enable traceback see: https://pytorch.org/docs/stable/elastic/errors.html
============================================================
